func myErrorFunction(throw_error: bool): Vector@(i32) {
    if (throw_error) {
        throw [50 + 430]
    } else {
        return [40]
    }
}

func main(): i32 {
    do {
        var x = try myErrorFunction(true)
        return x
    } catch (var e: i32) {
        print("ERROR IN FUNCTION")
        return -1
    }

    var y = try! myErrorFunction(false)
}
